Workbook

Sheet Use of Funds - Prior
B3: Use | C3: Amount | D3: What it pays for
B4: Project-owner acquisition | C4: 80000 | D4: $45,000 paid campaigns; $25,000 distribution partnerships and referral payments; $10,000 campaign content and landing pages
B5: Growth, sales and onboarding | C5: 45000 | D5: Three months: growth lead at $5,000/month; four qualification/onboarding specialists at $2,000/month each; $6,000 performance incentives
B6: Product and engineering | C6: 30000 | D6: Additional engineering and QA capacity for opportunity posting, credits, bidding, commission tracking and verification purchases
B7: Existing team and operations | C7: 30000 | D7: Three months of existing team compensation and operating support, including founder compensation if required
B8: Verification delivery capacity | C8: 25000 | D8: Verifier onboarding, inspections, travel, report review and quality control
B9: Infrastructure and administration | C9: 15000 | D9: $6,000 hosting, CRM and communication tools; $9,000 contracts, accounting and essential setup
B10: Protected 60-day operating buffer | C10: 75000 | D10: Continued operations during April–May, with spending capped at $37,500/month
B11: Total | C11: 300000 | D11: 90-day execution plan plus 60-day buffer
B15: Period | C15: Spending limit | D15: Required outcome
B16: January | C16: 120000 | D16: Acquire 150 qualified projects; begin paid bidding and verification
B17: February | C17: 55000 | D17: Convert hiring opportunities into awards and commissions; deliver verifications
B18: March | C18: 50000 | D18: Establish repeat verification purchases, collections and delivery margins
B19: April–May reserve | C19: 75000 | D19: Maintain operations while project revenue continues to arrive
B20: Total | C20: 300000

Sheet Revenue Model
A1: Verification
A2: Jalla Cost | B2: 0.015
A3: Average Project | B3: 150000
A4: Stages | B4: 8
A5: Stage Cost Average | B5: =B3/B4 -> 18750
A6: Verification Per Stage | B6: =B5*B2 -> 281.25
A7: Verification Rev | B7: =B6*B4 -> 2250 | C7: =B7*B22 -> 2250000
A9: Contractor Bidding | E9: Capital Needed | F9: 950000
A10: Cost per Credit | B10: 500 XAF | C10: 0.85 | E10: Projects Onboarded | F10: 1000
A11: Minimum Credit Needed | B11: 10 | E11: Revenue | F11: =F10*B20 -> 2667500
A12: Minimim Bids/Project | B12: 5
A13: Bid Rev/Project | B13: =C10*B11*B12 -> 42.5 | C13: =B13*B22 -> 42500
E14: Initial Raise | F14: 300000
A15: Project Win Commision | E15: Projects Onboarded | F15: 150
A16: Project Owner/ Contractor Fee | B16: =K28*B3 -> 7500 | E16: Revenue | F16: =F15*B20 -> 400125
A17: Jalla Cost % | B17: 0.05
A18: Revenue | B18: =B16*B17 -> 375 | C18: =B18*B22 -> 375000
A20: Total Rev/Jalla Project | B20: =B7+B13+B18 -> 2667.5
A22: Target # Of Jalla Originated Projects | B22: 1000
A23: Revenue Target | B23: =B22*B20 -> 2667500
A25: Market Size
A26: TAM(Total Addressable Market) | B26: =(B27/B28)*B29*B20 -> 5.5128333e+08
A27: SSA Migrants | B27: 31000000 | F27: Assumptions
A28: Eligible Migrant per Household | B28: 1.5 | C28: Assumed | F28: Project Owners are going to request verification at Every Stage | K28: 0.05
A29: Annual Projects Start Rate | B29: 0.01 | C29: Assumed | F29: Every Project will get Minimum Bids
F30: Revenue Per Project is Based on Jalla Originated clients. Done that way for simplicity of the model
A31: Current SAM(Total Serviceable Market) | B31: =(B32/B33)*B34*B20 -> 7113333.3 | F31: The only revenue driver will be Verification if Contractor Brings client and vice versa
A32: SSA Migrants | B32: 400000 | F32: Average project at $150,000
A33: Eligible Migrant per Household | B33: 1.5 | F33: Average project lifecycle is 7 months
A34: Annual Projects Start Rate | B34: 0.01 | F34: Every project produces Win Commission
A36: 12 Months SOM(Obtainable Market) | B36: =B37*B20 -> 2667500
A37: Projects | B37: 1000
A38: 3 Months SOM | B38: =B39*B20 -> 400125
A39: Projects | B39: 150

Sheet 2027 Rollout Plan (Project 1000
A1: Jalla — 2027 market opportunity and funded rollout
A2: Current plan: $950,000 funds January–December 2027; launch Cameroon, then Ghana and Nigeria. Original source tabs preserved.
A4: Investor summary | C4: USD / projects | E4: Interpretation
A5: SSA TAM — full uptake | C5: =C36 -> 5.5128333e+08 | E5: Full proposed fees from one year's qualifying new starts, at $150k reference budget.
A6: SSA comparison — adjusted uptake | C6: =C35*C31 -> 400520000 | E6: Sensitivity only; headline TAM uses full uptake.
A7: Initial Cameroon SAM — full uptake | C7: =H41 -> 4608728.7 | E7: USA, France and Canada corridors quantified.
A8: Planned three-country SAM — full uptake | C8: =H44 -> 18052929 | E8: Adds USA-funded Ghana/Nigeria; partial corridor coverage, conditional on operational launch.
A9: March 2027 SOM target | C9: =E51 -> 150 | E9: 150 cumulative qualified projects in Cameroon.
A10: December 2027 SOM target | C10: =E52 -> 1000 | E10: 1,000 cumulative qualified projects: Cameroon 150 + Ghana/Nigeria 850.
A11: Year-one cohort lifetime fees — adjusted | C11: =G53 -> 1938000 | E11: Conditional on activation and assumed uptake; not year-one earned revenue or cash.
A12: Year-one cohort lifetime fees — full uptake | C12: =H53 -> 2667500 | E12: Current proposed model's full-uptake case, not a guarantee.
A14: Shared assumptions and monetization | C14: Value | E14: Evidence / limitation
A15: Formula: migrant population ÷ migrants per household × 1% annual starts × modeled lifetime fees per project. No additional eligibility or coverage discount.
A17: SSA-origin international migrants | C17: ='Market Size'!C15 -> 31000000 | E17: UN DESA 2024 rounded 31m; includes intra-African migrants.
A18: Assumed migrants per funding household | C18: 1.5 | E18: Founder-accepted planning assumption; not measured household size.
A19: Annual qualifying project starts / household | C19: 0.01 | E19: Founder-accepted planning assumption; not observed participation.
A20: Average project lifecycle, months | C20: 7 | E20: Planning assumption; fees can extend beyond December 2027.
A22: SSA reference project budget | C22: ='Revenue Model'!B3 -> 150000 | E22: $150k assumption applied consistently to headline TAM/SAM; not a measured regional average.
A23: Three-country reference project budget | C23: ='Revenue Model'!B3 -> 150000 | E23: Same $150k assumption; country differences and local prices unvalidated.
A24: SOM verification stage-value uptake | C24: 0.75 | E24: Management assumption for forecast only; TAM/SAM use full uptake.
A25: SOM bid-monetized project share | C25: 0.6 | E25: Management assumption for forecast only; TAM/SAM use full uptake.
A26: SOM commission-eligible project share | C26: 0.6 | E26: Management assumption for forecast only; TAM/SAM use full uptake.
A27: Verification fee rate | C27: ='Revenue Model'!B2 -> 0.015 | E27: Proposed price, not evidence of realized uptake.
A28: Full bid revenue / eligible project | C28: ='Revenue Model'!B13 -> 42.5 | E28: Ghana/Nigeria local credit pricing not yet validated.
A29: Contractor professional fee / project budget | C29: ='Revenue Model'!K28 -> 0.05 | E29: Planning assumption.
A30: Jalla commission / contractor professional fee | C30: ='Revenue Model'!B17 -> 0.05 | E30: Commission is on contractor professional fees, not the whole project budget.
A31: SSA adjusted lifetime fees / project | C31: =C22*C27*C24+C28*C25+C22*C29*C30*C26 -> 1938 | E31: Sensitivity; same reference budget as TAM, with lower service uptake.
A32: Three-country adjusted lifetime fees / project | C32: =C23*C27*C24+C28*C25+C23*C29*C30*C26 -> 1938 | E32: $1,938 at current assumptions; conditional, not actual LTV.
A33: Three-country full-uptake lifetime fees / project | C33: ='Revenue Model'!B20 -> 2667.5 | E33: $2,667.50 at current proposed prices and full uptake.
A35: Annual SSA qualifying new project starts | C35: =C17/C18*C19 -> 206666.67
A36: SSA TAM — full-uptake lifetime fees | C36: =C35*C33 -> 5.5128333e+08
A37: Original Revenue Model TAM reference | C37: ='Revenue Model'!B26 -> 5.5128333e+08
A38: TAM/SAM use the proposed full-uptake fee of $2,667.50 per project at a $150k reference budget. SOM uses adjusted fees of $1,938 per project. Both price/budget and uptake inputs remain unvalidated.
A40: Construction market | B40: USA migrants | C40: France migrants | D40: Canada migrants | E40: Counted migrants | F40: Annual starts | G40: Fees / project | H40: Annual-cohort fees
A41: Cameroon | B41: 98000 | C41: ='Market Size'!C19 -> 127520 | D41: 33640 | E41: =SUM(B41:D41) -> 259160 | F41: =E41/$C$18*$C$19 -> 1727.7333 | G41: =$C$33 -> 2667.5 | H41: =F41*G41 -> 4608728.7
A42: Ghana | B42: 223000 | E42: =B42 -> 223000 | F42: =E42/$C$18*$C$19 -> 1486.6667 | G42: =$C$33 -> 2667.5 | H42: =F42*G42 -> 3965683.3
A43: Nigeria | B43: 533000 | E43: =B43 -> 533000 | F43: =E43/$C$18*$C$19 -> 3553.3333 | G43: =$C$33 -> 2667.5 | H43: =F43*G43 -> 9478516.7
A44: Three-country scope | B44: =SUM(B41:B43) -> 854000 | C44: =C41 -> 127520 | D44: =D41 -> 33640 | E44: =SUM(E41:E43) -> 1015160 | F44: =SUM(F41:F43) -> 6767.7333 | G44: =$C$33 -> 2667.5 | H44: =SUM(H41:H43) -> 18052929
A45: Blank Ghana/Nigeria France/Canada cells mean uncounted, not zero migrants. Other corridors are excluded. This partial SAM estimate does not represent the entire diaspora of these countries or a proven lower bound.
A46: Initial SAM is Cameroon; planned SAM adds Ghana/Nigeria after service launch. Fundraising alone does not establish operational coverage.
...

Sheet 2027 Rollout Plan(Project 2000)
A1: Jalla — revised worldwide SAM and 2,000-project rollout
A2: Plan revised 22 October 2026: $950,000 funds January–December 2027. Worldwide migrants from Cameroon, Ghana and Nigeria; every earlier tab preserved.
A4: Investor summary | C4: USD / projects | E4: Interpretation
A5: SSA TAM — full uptake | C5: =C36 -> 5.5128333e+08 | E5: Full proposed fees from one year's qualifying new starts, at $150k reference budget.
A6: SSA comparison — adjusted uptake | C6: =C35*C31 -> 400520000 | E6: Sensitivity only; headline TAM uses full uptake.
A7: Initial Cameroon SAM — full uptake | C7: =G41 -> 7285422.7 | E7: All worldwide Cameroon-origin international migrants, including intra-African destinations.
A8: Planned three-country SAM — full uptake | C8: =G44 -> 63285139 | E8: Worldwide migrants originating in Cameroon, Ghana and Nigeria; conditional on operational rollout.
A9: March 2027 SOM target | C9: =E51 -> 150 | E9: 150 cumulative qualified projects in Cameroon.
A10: December 2027 SOM target | C10: =E52 -> 2000 | E10: 2,000 cumulative qualified projects: Cameroon 150 + Ghana/Nigeria 1,850.
A11: Year-one cohort lifetime fees — adjusted | C11: =G53 -> 3876000 | E11: Conditional on activation and assumed uptake; not year-one earned revenue or cash.
A12: Year-one cohort lifetime fees — full uptake | C12: =H53 -> 5335000 | E12: Current proposed model's full-uptake case, not a guarantee.
A14: Shared assumptions and monetization | C14: Value | E14: Evidence / limitation
A15: Formula: migrant population ÷ migrants per household × 1% annual starts × modeled lifetime fees per project. No additional eligibility or coverage discount.
A16: 12-month cumulative qualified-project target | C16: 2000 | E16: Founder target revised from 1,000; acquisition/delivery forecast must substantiate it.
A17: SSA-origin international migrants | C17: ='Market Size'!C15 -> 31000000 | E17: UN DESA 2024 rounded 31m; includes intra-African migrants.
A18: Assumed migrants per funding household | C18: 1.5 | E18: Founder-accepted planning assumption; not measured household size.
A19: Annual qualifying project starts / household | C19: 0.01 | E19: Founder-accepted planning assumption; not observed participation.
A20: Average project lifecycle, months | C20: 7 | E20: Planning assumption; fees can extend beyond December 2027.
A22: SSA reference project budget | C22: ='Revenue Model'!B3 -> 150000 | E22: $150k assumption applied consistently to headline TAM/SAM; not a measured regional average.
A23: Three-country reference project budget | C23: ='Revenue Model'!B3 -> 150000 | E23: Same $150k assumption for all countries; local budgets and credit pricing unvalidated.
A24: SOM verification stage-value uptake | C24: 0.75 | E24: Management assumption for forecast only; TAM/SAM use full uptake.
A25: SOM bid-monetized project share | C25: 0.6 | E25: Management assumption for forecast only; TAM/SAM use full uptake.
A26: SOM commission-eligible project share | C26: 0.6 | E26: Management assumption for forecast only; TAM/SAM use full uptake.
A27: Verification fee rate | C27: ='Revenue Model'!B2 -> 0.015 | E27: Proposed price, not evidence of realized uptake.
A28: Full bid revenue / eligible project | C28: ='Revenue Model'!B13 -> 42.5 | E28: Ghana/Nigeria local credit pricing not yet validated.
A29: Contractor professional fee / project budget | C29: ='Revenue Model'!K28 -> 0.05 | E29: Planning assumption.
A30: Jalla commission / contractor professional fee | C30: ='Revenue Model'!B17 -> 0.05 | E30: Commission is on contractor professional fees, not the whole project budget.
A31: SSA adjusted lifetime fees / project | C31: =C22*C27*C24+C28*C25+C22*C29*C30*C26 -> 1938 | E31: Sensitivity; same reference budget as TAM, with lower service uptake.
A32: Three-country adjusted lifetime fees / project | C32: =C23*C27*C24+C28*C25+C23*C29*C30*C26 -> 1938 | E32: $1,938 at current assumptions; conditional, not actual LTV.
A33: Three-country full-uptake lifetime fees / project | C33: ='Revenue Model'!B20 -> 2667.5 | E33: $2,667.50 at current proposed prices and full uptake.
A35: Annual SSA qualifying new project starts | C35: =C17/C18*C19 -> 206666.67
A36: SSA TAM — full-uptake lifetime fees | C36: =C35*C33 -> 5.5128333e+08
A37: Original Revenue Model TAM reference | C37: ='Revenue Model'!B26 -> 5.5128333e+08
A38: TAM/SAM use the proposed full-uptake fee of $2,667.50 per project at a $150k reference budget. SOM uses adjusted fees of $1,938 per project. Both price/budget and uptake inputs remain unvalidated.
A40: Construction market | B40: Worldwide migrants | C40: Assumed households | D40: Annual starts | E40: Project budget | F40: Full fees / project | G40: Annual-cohort fees | H40: Population evidence
A41: Cameroon | B41: 409677 | C41: =B41/$C$18 -> 273118 | D41: =C41*$C$19 -> 2731.18 | E41: =$C$23 -> 150000 | F41: =$C$33 -> 2667.5 | G41: =D41*F41 -> 7285422.7 | H41: UN DESA 2024 via EUDiF; 409,677
A42: Ghana | B42: 1055000 | C42: =B42/$C$18 -> 703333.33 | D42: =C42*$C$19 -> 7033.3333 | E42: =$C$23 -> 150000 | F42: =$C$33 -> 2667.5 | G42: =D42*F42 -> 18761417 | H42: UN DESA 2024 via MPI; rounded 1,055,000
A43: Nigeria | B43: 2094000 | C43: =B43/$C$18 -> 1396000 | D43: =C43*$C$19 -> 13960 | E43: =$C$23 -> 150000 | F43: =$C$33 -> 2667.5 | G43: =D43*F43 -> 37238300 | H43: UN DESA 2024 via MPI; rounded 2,094,000
A44: Three-country scope | B44: =SUM(B41:B43) -> 3558677 | C44: =SUM(C41:C43) -> 2372451.3 | D44: =SUM(D41:D43) -> 23724.513 | E44: =$C$23 -> 150000 | F44: =$C$33 -> 2667.5 | G44: =SUM(G41:G43) -> 63285139 | H44: All destinations; no corridor exclusions
A45: Population scope is international migrant stock by country of origin, wherever migrants live. It generally excludes foreign-born descendants and does not count every person identifying as diaspora. No corridor restriction applies.
...

Sheet Budget Evidence
A1: Jalla — evidence and editable budget drivers
A2: Edit B for a planning revision. To use evidence: enter C, set D to Verified, add source G, scope H and review date J. E updates only when all fields are complete.
A4: Driver | B4: Planning value | C4: Verified value | D4: Evidence status | E4: Active value | F4: Unit | G4: Evidence / source URL | H4: Country / period / sample | I4: Suggested owner | J4: Reviewed date | K4: Next verification action
A5: Raise total | B5: 950000 | D5: Founder plan | E5: =IF(AND(D5="Verified",ISNUMBER(C5),G5<>"",H5<>"",J5<>""),C5,B5) -> 950000 | F5: USD | I5: Founder | K5: Confirm fundraising schedule
A6: First tranche | B6: 300000 | D6: Founder plan | E6: =IF(AND(D6="Verified",ISNUMBER(C6),G6<>"",H6<>"",J6<>""),C6,B6) -> 300000 | F6: USD | I6: Founder | K6: Confirm close date
A7: First phase months | B7: 3 | D7: Founder plan | E7: =IF(AND(D7="Verified",ISNUMBER(C7),G7<>"",H7<>"",J7<>""),C7,B7) -> 3 | F7: months | I7: Office Lead | K7: Jan–Mar 2027
A8: Expansion months | B8: 9 | D8: Founder plan | E8: =IF(AND(D8="Verified",ISNUMBER(C8),G8<>"",H8<>"",J8<>""),C8,B8) -> 9 | F8: months | I8: Office Lead | K8: Apr–Dec 2027
A9: First phase projects | B9: 150 | D9: Target | E9: =IF(AND(D9="Verified",ISNUMBER(C9),G9<>"",H9<>"",J9<>""),C9,B9) -> 150 | F9: projects | I9: Growth lead | K9: Deduplicated qualified and onboarded project records
A10: Annual projects — 1,000 case | B10: 1000 | D10: Target | E10: =IF(AND(D10="Verified",ISNUMBER(C10),G10<>"",H10<>"",J10<>""),C10,B10) -> 1000 | F10: projects | I10: Growth lead | K10: Build channel and capacity forecast
A11: Annual projects — 2,000 case | B11: 2000 | D11: Target | E11: =IF(AND(D11="Verified",ISNUMBER(C11),G11<>"",H11<>"",J11<>""),C11,B11) -> 2000 | F11: projects | I11: Growth lead | K11: Build channel and capacity forecast
A12: Founder compensation / month | B12: 5000 | D12: Founder confirmed budget | E12: =IF(AND(D12="Verified",ISNUMBER(C12),G12<>"",H12<>"",J12<>""),C12,B12) -> 5000 | F12: USD/month | I12: Founder | K12: Document compensation approval; currently unpaid
A13: Current team compensation / month | B13: 5000 | D13: Founder confirmed budget | E13: =IF(AND(D13="Verified",ISNUMBER(C13),G13<>"",H13<>"",J13<>""),C13,B13) -> 5000 | F13: USD/month | I13: Office Lead | K13: Reconcile named roster, contracts, fees and current payroll
A14: Local travel / month | B14: 900 | D14: Planning | E14: =IF(AND(D14="Verified",ISNUMBER(C14),G14<>"",H14<>"",J14<>""),C14,B14) -> 900 | F14: USD/month | I14: Operations lead | K14: Transport receipts; exclude routine inspection travel
A15: Verifier readiness / month | B15: 600 | D15: Planning | E15: =IF(AND(D15="Verified",ISNUMBER(C15),G15<>"",H15<>"",J15<>""),C15,B15) -> 600 | F15: USD/month | I15: Operations lead | K15: Vetting/training quotes; exclude launch setup
A16: Project coordination / month | B16: 450 | D16: Planning | E16: =IF(AND(D16="Verified",ISNUMBER(C16),G16<>"",H16<>"",J16<>""),C16,B16) -> 450 | F16: USD/month | I16: Operations lead | K16: Call/data/translation receipts; exclude software subscriptions
... A31: All-in routine verification cost | B31: 86 | D31: Founder-researched cost | E31: =IF(AND(D31="Verified",ISNUMBER(C31),G31<>"",H31<>"",J31<>""),C31,B31) -> 86 | F31: USD/inspection | I31: Operations lead | K31: Attach research/quotes; verify country, geography, taxes, reporting and date
A33: Evidence workflow
A34: Verified means supported by attached evidence, defined scope and review date. Founder-confirmed budgets are approved planning inputs, not historical spending or market validation.
A35: Updating these drivers recalculates Use Of Funds. Existing market/revenue tabs keep their own inputs; review them separately when monetization or demographic evidence changes.
A37: Priority gap | B37: Evidence required | C37: Suggested owner | D37: Current status
A38: Acquisition funnel and CAC | B38: Weekly spend, unique inquiries, qualified projects, onboarded projects, activated projects and paying owners by channel/country/corridor | C38: Growth lead | D38: Open
A39: Activation definition and conversion | B39: Agree milestone, deduplicate owners/projects, track qualification → onboarding → activation → paid service | C39: Product / Growth | D39: Open
A40: Acquisition corridor selection | B40: Owner pipeline and conversion data; worldwide SAM does not imply equal acquisition economics across locations | C40: Growth lead | D40: Open
A41: Staffing capacity | B41: Named roster; handling time; active project caseload; inspections/day; response time and workload thresholds | C41: Office Lead | D41: Open
A42: Country launch readiness | B42: Verifier coverage, payment rails, support language, contracts and launch dates for Ghana/Nigeria | C42: Operations / Technical | D42: Open
A43: Monthly cash and second close | B43: Monthly hiring, campaign spend, project arrivals, collection/delivery timing; second-close delay stress test | C43: Founder / Office Lead | D43: Open
A44: Service economics and uptake | B44: Country-stage budgets, actual fee charged, count/value uptake, refunds, processing fees, verified $86 cost applicability | C44: Operations lead | D44: Open
A45: Market inputs and population | B45: Original demographic tables/year; household divisor and annual starts remain assumptions until validated | C45: Founder | D45: Open
A46: Additional growth / engineering | B46: Check contracts, hiring costs, employer costs and overlap with existing compensation | C46: Office Lead | D46: Open
A47: Annual target feasibility | B47: Bottom-up monthly country/channel targets and capacity plan supporting 850 or 1,850 expansion projects | C47: Growth / Operations | D47: Open
A48: 2028 obligations | B48: Carry forward undelivered prepaid inspections, remaining fees and associated delivery costs | C48: Office Lead | D48: Open

Sheet Use Of Funds
A1: Jalla — 2027 use of funds: working budget
A2: Updated 22 October 2026. USD. Targets and unverified allocations are planning inputs; acquisition capacity and monthly cash flow remain to be demonstrated.
A3: Controls and evidence: Budget Evidence. Blue input values there are editable; formula outputs below recalculate.
A5: Use / metric | B5: Jan–Mar: 1,000 case | C5: Apr–Dec: 1,000 case | D5: Annual: 1,000 case | F5: Jan–Mar: 2,000 case | G5: Apr–Dec: 2,000 case | H5: Annual: 2,000 case | I5: Scope / interpretation
A6: Project-owner acquisition | B6: ='Budget Evidence'!E20 -> 105000 | C6: ='Budget Evidence'!E21 -> 150000 | D6: =SUM(B6:C6) -> 255000 | F6: =B6 -> 105000 | G6: ='Budget Evidence'!E22 -> 280000 | H6: =SUM(F6:G6) -> 385000 | I6: Campaigns, owner referrals, partnerships and content; channel budgets unvalidated
A7: Additional growth / sales / onboarding | B7: ='Budget Evidence'!E23 -> 45000 | C7: ='Budget Evidence'!E24 -> 90000 | D7: =SUM(B7:C7) -> 135000 | F7: =B7 -> 45000 | G7: ='Budget Evidence'!E25 -> 135000 | H7: =SUM(F7:G7) -> 180000 | I7: Incremental staff only; replace allowances with named hires and costs
A8: Additional product / engineering | B8: ='Budget Evidence'!E26 -> 30000 | C8: ='Budget Evidence'!E27 -> 60000 | D8: =SUM(B8:C8) -> 90000 | F8: =B8 -> 30000 | G8: =C8 -> 60000 | H8: =SUM(F8:G8) -> 90000 | I8: Incremental engineering and QA;
A9: Founder compensation | B9: ='Budget Evidence'!E12*'Budget Evidence'!E7 -> 15000 | C9: ='Budget Evidence'!E12*'Budget Evidence'!E8 -> 45000 | D9: =SUM(B9:C9) -> 60000 | F9: =B9 -> 15000 | G9: =C9 -> 45000 | H9: =SUM(F9:G9) -> 60000 | I9: $5,000/month planned; currently unpaid
A10: Current team compensation | B10: ='Budget Evidence'!E13*'Budget Evidence'!E7 -> 15000 | C10: ='Budget Evidence'!E13*'Budget Evidence'!E8 -> 45000 | D10: =SUM(B10:C10) -> 60000 | F10: =B10 -> 15000 | G10: =C10 -> 45000 | H10: =SUM(F10:G10) -> 60000 | I10: $5,000/month; obtain roster and contract evidence with planned increments
A11: Operations — non-payroll | B11: =SUM('Budget Evidence'!E14:E19)*'Budget Evidence'!E7 -> 9000 | C11: =SUM('Budget Evidence'!E14:E19)*'Budget Evidence'!E8 -> 27000 | D11: =SUM(B11:C11) -> 36000 | F11: =B11 -> 9000 | G11: =C11 -> 27000 | H11: =SUM(F11:G11) -> 36000 | I11: $3,000/month; six components below; excludes routine verification
A12: Infrastructure / administration | B12: ='Budget Evidence'!E28 -> 15000 | C12: ='Budget Evidence'!E29 -> 35000 | D12: =SUM(B12:C12) -> 50000 | F12: =B12 -> 15000 | G12: =C12 -> 35000 | H12: =SUM(F12:G12) -> 50000 | I12: Hosting, CRM/software, accounting/legal; itemize and reconcile operations overlap
A13: Ghana / Nigeria launches | B13: 0 | C13: ='Budget Evidence'!E30 -> 50000 | D13: =SUM(B13:C13) -> 50000 | F13: =B13 -> 0 | G13: =C13 -> 50000 | H13: =SUM(F13:G13) -> 50000 | I13: One-time country setup and initial recruitment; split/quotes not verified
A14: Planned deployment | B14: =SUM(B6:B13) -> 234000 | C14: =SUM(C6:C13) -> 502000 | D14: =SUM(B14:C14) -> 736000 | F14: =SUM(F6:F13) -> 234000 | G14: =SUM(G6:G13) -> 677000 | H14: =SUM(F14:G14) -> 911000 | I14: Excludes routine client-prepaid verification costs
A15: Capital raised / planned funding | B15: ='Budget Evidence'!E6 -> 300000 | C15: ='Budget Evidence'!E5-B15 -> 650000 | D15: =SUM(B15:C15) -> 950000 | F15: =B15 -> 300000 | G15: =C15 -> 650000 | H15: =SUM(F15:G15) -> 950000 | I15: Financing targets; not received cash
A16: Reserve movement / annual retained reserve | B16: =B15-B14 -> 66000 | C16: =C15-C14 -> 148000 | D16: =D15-D14 -> 214000 | F16: =F15-F14 -> 66000 | G16: =G15-G14 -> -27000 | H16: =H15-H14 -> 39000 | I16: Negative expansion movement draws on first-phase reserve; annual column is retained reserve
A17: Allocated including reserve | B17: =SUM(B14,B16) -> 300000 | C17: =SUM(C14,C16) -> 650000 | D17: =SUM(D14,D16) -> 950000 | F17: =SUM(F14,F16) -> 300000 | G17: =SUM(G14,G16) -> 650000 | H17: =SUM(H14,H16) -> 950000 | I17: Capital reconciliation; reserve counted once
A18: Capital check — zero | B18: =B15-B17 -> 0 | C18: =C15-C17 -> 0 | D18: =D15-D17 -> 0 | F18: =F15-F17 -> 0 | G18: =G15-G17 -> 0 | H18: =H15-H17 -> 0 | I18: Zero means arithmetic reconciles; does not validate costs
A20: Acquisition targets and budget intensity
A21: Qualified AND onboarded projects | B21: ='Budget Evidence'!E9 -> 150 | C21: ='Budget Evidence'!E10-B21 -> 850 | D21: =SUM(B21:C21) -> 1000 | F21: =B21 -> 150 | G21: ='Budget Evidence'!E11-F21 -> 1850 | H21: =SUM(F21:G21) -> 2000 | I21: Confirmed owner, scope/budget, active hiring need and completed setup; activation/payment tracked separately
A22: Direct acquisition budget / project | B22: =B6/B21 -> 700 | C22: =C6/C21 -> 176.47059 | D22: =D6/D21 -> 255 | F22: =F6/F21 -> 700 | G22: =G6/G21 -> 151.35135 | H22: =H6/H21 -> 192.5 | I22: Budget intensity, not demonstrated CAC
A23: Acquisition + additional growth / project | B23: =SUM(B6:B7)/B21 -> 1000 | C23: =SUM(C6:C7)/C21 -> 282.35294 | D23: =SUM(D6:D7)/D21 -> 390 | F23: =SUM(F6:F7)/F21 -> 1000 | G23: =SUM(G6:G7)/G21 -> 224.32432 | H23: =SUM(H6:H7)/H21 -> 282.5 | I23: Excludes current payroll and engineering; not fully loaded CAC
A24: Average projects onboarded / month | B24: =B21/'Budget Evidence'!E7 -> 50 | C24: =C21/'Budget Evidence'!E8 -> 94.444444 | D24: =D21/SUM('Budget Evidence'!E7:E8) -> 83.333333 | F24: =F21/'Budget Evidence'!E7 -> 50 | G24: =G21/'Budget Evidence'!E8 -> 205.55556 | H24: =H21/SUM('Budget Evidence'!E7:E8) -> 166.66667 | I24: Required throughput; no capacity evidence yet
A25: Cash carried from first phase | B25: 0 | C25: =B16 -> 66000 | F25: =B25 -> 0 | G25: =F16 -> 66000 | I25: Reserve carried forward, not a new raise
A26: Closing cash before revenue | B26: =B15-B14 -> 66000 | C26: =C25+C15-C14 -> 214000 | D26: =C26 -> 214000 | F26: =F15-F14 -> 66000 | G26: =G25+G15-G14 -> 39000 | H26: =G26 -> 39000 | I26: Phase totals only; not a monthly cash/runway forecast
A27: Team compensation subtotal | B27: =SUM(B9:B10) -> 30000 | C27: =SUM(C9:C10) -> 90000 | D27: =SUM(D9:D10) -> 120000 | F27: =SUM(F9:F10) -> 30000 | G27: =SUM(G9:G10) -> 90000 | H27: =SUM(H9:H10) -> 120000 | I27: Included above, do not add again
A29: Operations detail — included in row 11 | B29: Monthly USD | C29: Annual USD | D29: Boundary
A30: Local travel / month | B30: ='Budget Evidence'!E14 -> 900 | C30: =B30*SUM('Budget Evidence'!E7:E8) -> 10800 | D30: Exclude routine inspection transport
A31: Verifier readiness / month | B31: ='Budget Evidence'!E15 -> 600 | C31: =B31*SUM('Budget Evidence'!E7:E8) -> 7200 | D31: Ongoing vetting/training; initial market setup in launches
A32: Project coordination / month | B32: ='Budget Evidence'!E16 -> 450 | C32: =B32*SUM('Budget Evidence'!E7:E8) -> 5400 | D32: Calls/data/translation; subscription software in infrastructure
A33: Quality and issue resolution / month | B33: ='Budget Evidence'!E17 -> 600 | C33: =B33*SUM('Budget Evidence'!E7:E8) -> 7200 | D33: Exceptional reviews and investigations; routine inspection QA within $86
A34: Supplies / month | B34: ='Budget Evidence'!E18 -> 150 | C34: =B34*SUM('Budget Evidence'!E7:E8) -> 1800 | D34: Project/field supplies only
A35: Operations contingency / month | B35: ='Budget Evidence'!E19 -> 300 | C35: =B35*SUM('Budget Evidence'!E7:E8) -> 3600 | D35: Within operations; separate from overall reserve
A36: Total operations | B36: =SUM(B30:B35) -> 3000 | C36: =SUM(C30:C35) -> 36000 | D36: Included above
A38: Verification delivery treatment
A39: All-in cost / routine inspection | B39: ='Budget Evidence'!E31 -> 86 | C39: Founder-researched, evidence not attached; country applicability to validate
A40: Funding mechanism | B40: Client pays before activation; routine inspection cost is paid from that verification fee.
A41: Raise allocation for routine inspections | B41: 0 | C41: No routine inspection subsidy or working capital assumed. Refunds/settlement issues need a separate cash assessment.
A42: Delivery accounting | B42: Deduct delivery costs from fee revenue when assessing gross profit; prepaid client balances are not free growth cash.
A44: Team workflow
A45: 1. Replace planning values in Budget Evidence with better planning inputs as research progresses.
...

Sheet Revenue Timing
A1: Revenue timing — January 2027 project cohort
A2: FORECAST ONLY. Full uptake is unvalidated. Actual transactions belong in the tracker below.
A3: Qualified Jalla-sourced projects | B3: ='Revenue Model'!F15 -> 150
A4: Project lifecycle (months; fixed for this schedule) | B4: 7
A5: Share of stage value independently verified | B5: 1
A6: Share of projects receiving the modeled paid bids | B6: 1
A7: Share of projects generating an eligible commission | B7: 1
A8: Winning-bid deduction per awarded project (USD) | B8: 0
A9: Commission cash collection delay (whole months, 0–1) | B9: 1
A10: Direct delivery cost per inspection (USD)
A11: Collection / processing cost (% of revenue)
A12: Other direct lifetime delivery costs for cohort (USD)
A13: Blue cells are editable assumptions. Blank cost inputs mean margins are not yet established.
A14: Full-uptake lifetime revenue per project | B14: ='Revenue Model'!B20 -> 2667.5
A15: Assumption-adjusted lifetime revenue per project | B15: ='Revenue Model'!B7*B5+'Revenue Model'!B13*B6+MAX(0,'Revenue Model'!B18-B8)*B7 -> 2667.5
A16: Assumption-adjusted cohort lifetime revenue | B16: =B3*B15 -> 400125
A17: Lifetime direct delivery costs (requires all 3 cost inputs) | B17: =IF(COUNT(B10:B12)<3,"",B3*'Revenue Model'!B4*B5*B10+B16*B11+B12)
A18: Lifetime gross profit before operating expenses | B18: =IF(B17="","",B16-B17)
A19: Lifetime gross margin | B19: =IF(OR(B17="",B16=0),"",B18/B16)
A20: Illustrative monthly schedule. Same-month verification and bid payment; delayed commission collection.
A21: Forecast (USD unless stated) | B21: Jan 2027 | C21: Feb 2027 | D21: Mar 2027 | E21: Apr 2027 | F21: May 2027 | G21: Jun 2027 | H21: Jul 2027 | I21: Aug 2027 | J21: Total / end
A22: Inspection stages completed per project | B22: 1 | C22: 1 | D22: 1 | E22: 1 | F22: 1 | G22: 1 | H22: ='Revenue Model'!B4-SUM(B22:G22) -> 2 | I22: 0 | J22: =SUM(B22:I22) -> 8
A23: Share of modeled bids consumed | B23: 1 | C23: 0 | D23: 0 | E23: 0 | F23: 0 | G23: 0 | H23: 0 | I23: 0 | J23: =SUM(B23:I23) -> 1
A24: Share of eligible contractor fees received | B24: =1/$B$4 -> 0.14285714 | C24: =1/$B$4 -> 0.14285714 | D24: =1/$B$4 -> 0.14285714 | E24: =1/$B$4 -> 0.14285714 | F24: =1/$B$4 -> 0.14285714 | G24: =1/$B$4 -> 0.14285714 | H24: =1/$B$4 -> 0.14285714 | I24: 0 | J24: =SUM(B24:I24) -> 1
A25: Verification revenue earned | B25: =$B$3*'Revenue Model'!B7*$B$5*B22/'Revenue Model'!B4 -> 42187.5 | C25: =$B$3*'Revenue Model'!B7*$B$5*C22/'Revenue Model'!B4 -> 42187.5 | D25: =$B$3*'Revenue Model'!B7*$B$5*D22/'Revenue Model'!B4 -> 42187.5 | E25: =$B$3*'Revenue Model'!B7*$B$5*E22/'Revenue Model'!B4 -> 42187.5 | F25: =$B$3*'Revenue Model'!B7*$B$5*F22/'Revenue Model'!B4 -> 42187.5 | G25: =$B$3*'Revenue Model'!B7*$B$5*G22/'Revenue Model'!B4 -> 42187.5 | H25: =$B$3*'Revenue Model'!B7*$B$5*H22/'Revenue Model'!B4 -> 84375 | I25: =$B$3*'Revenue Model'!B7*$B$5*I22/'Revenue Model'!B4 -> 0 | J25: =SUM(B25:I25) -> 337500
A26: Bid-credit revenue earned on consumption | B26: =$B$3*'Revenue Model'!B13*$B$6*B23 -> 6375 | C26: =$B$3*'Revenue Model'!B13*$B$6*C23 -> 0 | D26: =$B$3*'Revenue Model'!B13*$B$6*D23 -> 0 | E26: =$B$3*'Revenue Model'!B13*$B$6*E23 -> 0 | F26: =$B$3*'Revenue Model'!B13*$B$6*F23 -> 0 | G26: =$B$3*'Revenue Model'!B13*$B$6*G23 -> 0 | H26: =$B$3*'Revenue Model'!B13*$B$6*H23 -> 0 | I26: =$B$3*'Revenue Model'!B13*$B$6*I23 -> 0 | J26: =SUM(B26:I26) -> 6375
A27: Commission earned on eligible contractor receipts | B27: =$B$3*MAX(0,'Revenue Model'!B18-$B$8)*$B$7*B24 -> 8035.7143 | C27: =$B$3*MAX(0,'Revenue Model'!B18-$B$8)*$B$7*C24 -> 8035.7143 | D27: =$B$3*MAX(0,'Revenue Model'!B18-$B$8)*$B$7*D24 -> 8035.7143 | E27: =$B$3*MAX(0,'Revenue Model'!B18-$B$8)*$B$7*E24 -> 8035.7143 | F27: =$B$3*MAX(0,'Revenue Model'!B18-$B$8)*$B$7*F24 -> 8035.7143 | G27: =$B$3*MAX(0,'Revenue Model'!B18-$B$8)*$B$7*G24 -> 8035.7143 | H27: =$B$3*MAX(0,'Revenue Model'!B18-$B$8)*$B$7*H24 -> 8035.7143 | I27: =$B$3*MAX(0,'Revenue Model'!B18-$B$8)*$B$7*I24 -> 0 | J27: =SUM(B27:I27) -> 56250
A28: Total revenue earned | B28: =SUM(B25:B27) -> 56598.214 | C28: =SUM(C25:C27) -> 50223.214 | D28: =SUM(D25:D27) -> 50223.214 | E28: =SUM(E25:E27) -> 50223.214 | F28: =SUM(F25:F27) -> 50223.214 | G28: =SUM(G25:G27) -> 50223.214 | H28: =SUM(H25:H27) -> 92410.714 | I28: =SUM(I25:I27) -> 0 | J28: =SUM(B28:I28) -> 400125
A29: Verification cash collected | B29: =B25 -> 42187.5 | C29: =C25 -> 42187.5 | D29: =D25 -> 42187.5 | E29: =E25 -> 42187.5 | F29: =F25 -> 42187.5 | G29: =G25 -> 42187.5 | H29: =H25 -> 84375 | I29: =I25 -> 0 | J29: =SUM(B29:I29) -> 337500
A30: Credit-purchase cash collected | B30: =B26 -> 6375 | C30: =C26 -> 0 | D30: =D26 -> 0 | E30: =E26 -> 0 | F30: =F26 -> 0 | G30: =G26 -> 0 | H30: =H26 -> 0 | I30: =I26 -> 0 | J30: =SUM(B30:I30) -> 6375
A31: Commission cash collected | B31: =IF($B$9=0,B27,0) -> 0 | C31: =IF($B$9=0,C27,B27) -> 8035.7143 | D31: =IF($B$9=0,D27,C27) -> 8035.7143 | E31: =IF($B$9=0,E27,D27) -> 8035.7143 | F31: =IF($B$9=0,F27,E27) -> 8035.7143 | G31: =IF($B$9=0,G27,F27) -> 8035.7143 | H31: =IF($B$9=0,H27,G27) -> 8035.7143 | I31: =IF($B$9=0,I27,H27) -> 8035.7143 | J31: =SUM(B31:I31) -> 56250
A32: Total customer cash collected | B32: =SUM(B29:B31) -> 48562.5 | C32: =SUM(C29:C31) -> 50223.214 | D32: =SUM(D29:D31) -> 50223.214 | E32: =SUM(E29:E31) -> 50223.214 | F32: =SUM(F29:F31) -> 50223.214 | G32: =SUM(G29:G31) -> 50223.214 | H32: =SUM(H29:H31) -> 92410.714 | I32: =SUM(I29:I31) -> 8035.7143 | J32: =SUM(B32:I32) -> 400125
A33: Cumulative revenue earned | B33: =SUM($B28:B28) -> 56598.214 | C33: =SUM($B28:C28) -> 106821.43 | D33: =SUM($B28:D28) -> 157044.64 | E33: =SUM($B28:E28) -> 207267.86 | F33: =SUM($B28:F28) -> 257491.07 | G33: =SUM($B28:G28) -> 307714.29 | H33: =SUM($B28:H28) -> 400125 | I33: =SUM($B28:I28) -> 400125 | J33: =I33 -> 400125
A34: Cumulative customer cash | B34: =SUM($B32:B32) -> 48562.5 | C34: =SUM($B32:C32) -> 98785.714 | D34: =SUM($B32:D32) -> 149008.93 | E34: =SUM($B32:E32) -> 199232.14 | F34: =SUM($B32:F32) -> 249455.36 | G34: =SUM($B32:G32) -> 299678.57 | H34: =SUM($B32:H32) -> 392089.29 | I34: =SUM($B32:I32) -> 400125 | J34: =I34 -> 400125
A35: Earned but uncollected balance | B35: =MAX(0,SUM($B25:B25)-SUM($B29:B29))+MAX(0,SUM($B26:B26)-SUM($B30:B30))+MAX(0,SUM($B27:B27)-SUM($B31:B31)) -> 8035.7143 | C35: =MAX(0,SUM($B25:C25)-SUM($B29:C29))+MAX(0,SUM($B26:C26)-SUM($B30:C30))+MAX(0,SUM($B27:C27)-SUM($B31:C31)) -> 8035.7143 | D35: =MAX(0,SUM($B25:D25)-SUM($B29:D29))+MAX(0,SUM($B26:D26)-SUM($B30:D30))+MAX(0,SUM($B27:D27)-SUM($B31:D31)) -> 8035.7143 | E35: =MAX(0,SUM($B25:E25)-SUM($B29:E29))+MAX(0,SUM($B26:E26)-SUM($B30:E30))+MAX(0,SUM($B27:E27)-SUM($B31:E31)) -> 8035.7143 | F35: =MAX(0,SUM($B25:F25)-SUM($B29:F29))+MAX(0,SUM($B26:F26)-SUM($B30:F30))+MAX(0,SUM($B27:F27)-SUM($B31:F31)) -> 8035.7143 | G35: =MAX(0,SUM($B25:G25)-SUM($B29:G29))+MAX(0,SUM($B26:G26)-SUM($B30:G30))+MAX(0,SUM($B27:G27)-SUM($B31:G31)) -> 8035.7143 | H35: =MAX(0,SUM($B25:H25)-SUM($B29:H29))+MAX(0,SUM($B26:H26)-SUM($B30:H30))+MAX(0,SUM($B27:H27)-SUM($B31:H31)) -> 8035.7143 | I35: =MAX(0,SUM($B25:I25)-SUM($B29:I29))+MAX(0,SUM($B26:I26)-SUM($B30:I30))+MAX(0,SUM($B27:I27)-SUM($B31:I31)) -> 0 | J35: =I35 -> 0
A36: Prepaid / unearned customer cash balance | B36: =MAX(0,SUM($B29:B29)-SUM($B25:B25))+MAX(0,SUM($B30:B30)-SUM($B26:B26))+MAX(0,SUM($B31:B31)-SUM($B27:B27)) -> 0 | C36: =MAX(0,SUM($B29:C29)-SUM($B25:C25))+MAX(0,SUM($B30:C30)-SUM($B26:C26))+MAX(0,SUM($B31:C31)-SUM($B27:C27)) -> 0 | D36: =MAX(0,SUM($B29:D29)-SUM($B25:D25))+MAX(0,SUM($B30:D30)-SUM($B26:D26))+MAX(0,SUM($B31:D31)-SUM($B27:D27)) -> 0 | E36: =MAX(0,SUM($B29:E29)-SUM($B25:E25))+MAX(0,SUM($B30:E30)-SUM($B26:E26))+MAX(0,SUM($B31:E31)-SUM($B27:E27)) -> 0 | F36: =MAX(0,SUM($B29:F29)-SUM($B25:F25))+MAX(0,SUM($B30:F30)-SUM($B26:F26))+MAX(0,SUM($B31:F31)-SUM($B27:F27)) -> 0 | G36: =MAX(0,SUM($B29:G29)-SUM($B25:G25))+MAX(0,SUM($B30:G30)-SUM($B26:G26))+MAX(0,SUM($B31:G31)-SUM($B27:G27)) -> 0 | H36: =MAX(0,SUM($B29:H29)-SUM($B25:H25))+MAX(0,SUM($B30:H30)-SUM($B26:H26))+MAX(0,SUM($B31:H31)-SUM($B27:H27)) -> 0 | I36: =MAX(0,SUM($B29:I29)-SUM($B25:I25))+MAX(0,SUM($B30:I30)-SUM($B26:I26))+MAX(0,SUM($B31:I31)-SUM($B27:I27)) -> 0 | J36: =I36 -> 0
A37: Lifetime estimate still unearned | B37: =MAX(0,$B$16-B33) -> 343526.79 | C37: =MAX(0,$B$16-C33) -> 293303.57 | D37: =MAX(0,$B$16-D33) -> 243080.36 | E37: =MAX(0,$B$16-E33) -> 192857.14 | F37: =MAX(0,$B$16-F33) -> 142633.93 | G37: =MAX(0,$B$16-G33) -> 92410.714 | H37: =MAX(0,$B$16-H33) -> 0 | I37: =MAX(0,$B$16-I33) -> 0 | J37: =I37 -> 0
A38: Revenue/cash reconciliation (must be zero) | B38: =ROUND(B33+B36-B34-B35,8) -> 0 | C38: =ROUND(C33+C36-C34-C35,8) -> 0 | D38: =ROUND(D33+D36-D34-D35,8) -> 0 | E38: =ROUND(E33+E36-E34-E35,8) -> 0 | F38: =ROUND(F33+F36-F34-F35,8) -> 0 | G38: =ROUND(G33+G36-G34-G35,8) -> 0 | H38: =ROUND(H33+H36-H34-H35,8) -> 0 | I38: =ROUND(I33+I36-I34-I35,8) -> 0 | J38: =I38 -> 0
A40: Budgeted operating cash outflow | B40: ='Use Of Funds'!C16 -> 148000 | C40: ='Use Of Funds'!C17 -> 650000 | D40: ='Use Of Funds'!C18 -> 0 | E40: ='Use Of Funds'!$C$19/2 -> 0 | F40: ='Use Of Funds'!$C$19/2 -> 0 | J40: =SUM(B40:I40) -> 798000
A41: Financing cash inflow (excluded from revenue) | B41: ='Revenue Model'!F14 -> 300000 | C41: 0 | D41: 0 | E41: 0 | F41: 0 | G41: 0 | H41: 0 | I41: 0 | J41: =SUM(B41:I41) -> 300000
...

Sheet Market Size
A1: Jalla market sizing — remote residential construction in Sub-Saharan Africa
A2: Desktop estimate, 21 October 2026. Demographic inputs are sourced; eligibility, project incidence, pricing uptake and coverage are assumptions.
A3: Selected scenario | C3: Base
A5: Investor summary | C5: Selected estimate | E5: Scope / interpretation
A6: TAM: revenue potential of annual new-project cohort | C6: =C66 -> 94069500 | E6: SSA-origin diaspora; conditional lifecycle service fees
A7: Initial quantified SAM: annual project-cohort revenue | C7: =C82 -> 1406305.8 | E7: Cameroon builds funded from USA, France and Canada; service-coverage assumption
A8: Initial SOM: qualified projects | C8: =C89 -> 150 | E8: January 2027 management acquisition target, not demonstrated demand
A9: Initial SOM: adjusted lifetime revenue potential | C9: =C90 -> 290700 | E9: Cohort lifetime potential; not earned revenue, cash, ARR or annual bookings
A10: Initial SOM: full-uptake lifetime revenue ceiling | C10: =C91 -> 400125 | E10: Existing Revenue Model; all stages verified and all modeled bidding / awards
A11: Annual new projects implied by TAM | C11: =C59 -> 72333.333 | E11: Estimated unique starts per year, not active project stock
A12: Annual serviceable starts implied by initial SAM | C12: =C77 -> 725.648 | E12: Partial Cameroon SAM; other funding countries excluded
A14: Published inputs and existing Jalla commercial inputs | C14: Value | G14: Evidence class | H14: Source / limitation
A15: SSA-origin international migrants, 2024 (rounded) | C15: 31000000 | G15: Published data | H15: UN DESA International Migrant Stock 2024 summary. Includes intra-African migrants and minors; descendants excluded.
A16: Cameroon-born residents in USA, 2024 | C16: 98000 | G16: Published data | H16: MPI's own tabulation of U.S. Census ACS 2024; first-generation population, not households.
A17: Total immigrants in France, 2025 (provisional) | C17: 7970000 | G17: Published data | H17: INSEE: L'essentiel sur les immigrés et les étrangers; 2025 provisional total.
A18: Cameroon share of immigrants in France, 2025 | C18: 0.016 | G18: Published data | H18: INSEE 2025 rounded share; derived Cameroon count is approximate.
A19: Derived Cameroon-origin immigrants in France | C19: =C17*C18 -> 127520 | G19: Derived from published data | H19: Uses rounded total/share; not an exact census count.
A20: Cameroon-born residents in Canada, 2021 | C20: 33640 | G20: Published data | H20: Statistics Canada table 98-10-0307-01: total Cameroon-born persons in private households, not just 28,755 landed immigrants.
A21: Population proxy across three funding corridors | C21: =SUM(C16,C19,C20) -> 259160 | G21: Derived mixed-year proxy | H21: USA 2024 + France 2025 + Canada 2021. Not a contemporaneous census. Migration between dates can cause overlap; no growth assumed.
A22: SSA personal remittances received, 2024 (USD) | C22: 5.7220392e+10 | G22: Published data | H22: World Bank WDI API, BX.TRF.PWKR.CD.DT; SSF. Retrieved 21 Oct 2026, dataset updated 8 Oct 2026.
A23: Cameroon personal remittances received, 2024 (USD) | C23: 6.90153e+08 | G23: Published data | H23: World Bank WDI API, BX.TRF.PWKR.CD.DT; CMR. Context only; not the construction market.
A24: Jalla reference project value | C24: ='Revenue Model'!B3 -> 150000 | G24: Jalla planning input | H24: Existing commercial model. Not a measured national or regional average.
A25: Verification fee rate | C25: ='Revenue Model'!B2 -> 0.015 | G25: Jalla proposed price | H25: Existing Revenue Model.
A26: Bid revenue for one fully bid opportunity | C26: ='Revenue Model'!B13 -> 42.5 | G26: Jalla proposed price | H26: Cameroon bid pricing used as an unvalidated regional proxy; country pricing will differ.
A27: Contractor fee as share of project budget | C27: ='Revenue Model'!K28 -> 0.05 | G27: Jalla planning input | H27: Separate professional fee, not contractor profit or total contract receipts.
A28: Jalla commission on eligible contractor fee | C28: ='Revenue Model'!B17 -> 0.05 | G28: Jalla proposed price | H28: Applies only to an eligible Jalla-originated hire.
A29: Project lifecycle (months) | C29: 7 | G29: Founder assumption | H29: Average provided by founder; not established by regional project data.
A30: Winning-bid deduction per award | C30: ='Revenue Timing'!B8 -> 0 | G30: Jalla proposed term | H30: Current setting linked from Revenue Timing; no deduction is assumed unless changed there.
A32: Scenario assumptions — all unvalidated; blue inputs are editable | C32: Active | D32: Low | E32: Base | F32: High | G32: Class | H32: Rationale / limitation
A33: Global eligibility share | C33: =INDEX(D33:F33,1,MATCH($C$3,$D$32:$F$32,0)) -> 0.35 | D33: 0.25 | E33: 0.35 | F33: 0.45 | G33: Management assumption | H33: Excludes people without financial capacity or a plausible owner role. Judgment, not measured from UN data.
A34: Eligible migrants per unique funding household | C34: =INDEX(D34:F34,1,MATCH($C$3,$D$32:$F$32,0)) -> 1.5 | D34: 1.5 | E34: 1.5 | F34: 1.5 | G34: Management assumption | H34: Household adjustment to reduce person-count duplication. No published diaspora-specific average.
A35: Annual unique new-project starts per eligible household | C35: =INDEX(D35:F35,1,MATCH($C$3,$D$32:$F$32,0)) -> 0.01 | D35: 0.005 | E35: 0.01 | F35: 0.02 | G35: Management assumption | H35: 0.5–2% incidence sensitivity; base means one start per 100 household-years. Not observed behavior.
A36: SSA average project budget (USD) | C36: =INDEX(D36:F36,1,MATCH($C$3,$D$32:$F$32,0)) -> 100000 | D36: 75000 | E36: 100000 | F36: 150000 | G36: Management assumption | H36: Base is below Jalla's $150k reference; judgment, not a verified regional average.
A37: SSA share of stage value buying verification | C37: =INDEX(D37:F37,1,MATCH($C$3,$D$32:$F$32,0)) -> 0.75 | D37: 0.5 | E37: 0.75 | F37: 1 | G37: Management assumption | H37: Purchase uptake scenario, not Jalla market share.
A38: SSA share receiving modeled paid bids | C38: =INDEX(D38:F38,1,MATCH($C$3,$D$32:$F$32,0)) -> 0.6 | D38: 0.4 | E38: 0.6 | F38: 0.8 | G38: Management assumption | H38: Eligible procurement / paid-bid activity proxy. No observed conversion data.
A39: SSA share generating an eligible commission | C39: =INDEX(D39:F39,1,MATCH($C$3,$D$32:$F$32,0)) -> 0.6 | D39: 0.4 | E39: 0.6 | F39: 0.8 | G39: Management assumption | H39: Successful eligible contractor awards; no validated conversion data.
A40: Core-corridor eligibility share | C40: =INDEX(D40:F40,1,MATCH($C$3,$D$32:$F$32,0)) -> 0.6 | D40: 0.4 | E40: 0.6 | F40: 0.7 | G40: Management assumption | H40: USA/France/Canada financial/owner eligibility assumption. Income context does not measure this share.
A41: Core-corridor migrants per funding household | C41: =INDEX(D41:F41,1,MATCH($C$3,$D$32:$F$32,0)) -> 1.5 | D41: 1.5 | E41: 1.5 | F41: 1.5 | G41: Management assumption | H41: Same unvalidated household adjustment.
A42: Core-corridor annual project-start rate | C42: =INDEX(D42:F42,1,MATCH($C$3,$D$32:$F$32,0)) -> 0.01 | D42: 0.005 | E42: 0.01 | F42: 0.02 | G42: Management assumption | H42: Annual starts assumption; existing construction stock not additionally counted.
A43: Cameroon operational service-coverage share | C43: =INDEX(D43:F43,1,MATCH($C$3,$D$32:$F$32,0)) -> 0.7 | D43: 0.5 | E43: 0.7 | F43: 0.9 | G43: Management assumption | H43: Share of prospective project locations/scopes Jalla could serve; requires delivery coverage, not a current measured map.
...

Sheet Cap Table - Working
A1: Jalla — working cap table and financing model
A2: Planning document • 22 October 2026 • One $950k round with rolling closes; $300k operational threshold and proposed early allocation.
A3: Current ownership is founder-reported. Projected percentages are conditional cap-based conversion, not issued shares or agreed investor terms.
A4: Control / assumption | B4: Active value | C4: Status / scope
A5: Selected negotiation scenario | B5: Opening | C5: Choose Opening or Alternative; proposal only
A6: Total equity raise target | B6: ='Budget Evidence'!E5 -> 950000 | C6: Includes relative $20k only in the conditional equity illustration
A7: Early allocation / deployment threshold | B7: ='Budget Evidence'!E6 -> 300000 | C7: First funds received under signed agreements; commitments alone do not qualify
A8: Early cap reduction | B8: 0.1 | C8: 10% lower cap; no additional conversion discount assumed
A9: Employee pool target after modeled SAFE conversion | B9: 0.1 | C9: Unallocated reserve; no employee grants established; before future new-money dilution
A10: Combined investor dilution ceiling | B10: 0.2 | C10: Negotiation ceiling in this cap-conversion model, not guaranteed final dilution
A11: First Investor— conditional equity allocation | B11: ='Investor Register'!B5 -> 20000 | C11: Terms unresolved; $13k cash received, $7k not received
A12: Prospective investor — conditional allocation | B12: ='Investor Register'!B6 -> 50000 | C12: $50k verbal interest; independent due diligence pending; unsigned and unfunded
A14: Derived financing terms | B14: Active value | C14: Interpretation
A15: Standard post-money cap | B15: =IF(B5="Opening",B20,C20) -> 7000000 | C15: Proposed cap; not an independently supported valuation
A16: Early post-money cap | B16: =B15*(1-B8) -> 6300000 | C16: Applies only if early terms are agreed and funded
A17: Standard allocation | B17: =B6-B7 -> 650000 | C17: Balance of the single financing plan
A19: Scenario inputs | B19: Opening | C19: Alternative
A20: Standard post-money cap | B20: 7000000 | C20: 6000000
A22: Authorized shares | C22: Unknown — obtain articles/amendments; do not assume a standard share count
A23: Founder shares actually issued | C23: Unknown — obtain stock ledger and issuance approvals
A24: Current founder ownership | B24: 1 | C24: Sole shareholder per founder.
A26: Full-raise illustration — NOT current ownership
A27: Holder / allocation | B27: Modeled capital USD | C27: Proposed cap USD | D27: Modeled ownership | E27: Basis / status
A28: Founder | B28: 0 | D28: =1-SUM(D30:D33)-D29 -> 0.75952381 | E28: Residual after investors and 10% employee pool
A29: Unallocated employee pool | B29: 0 | D29: =$B$9 -> 0.1 | E29: Target reserve, not employee stock already granted
A30: First Investor — if converted to agreed SAFE | B30: =$B$11 -> 20000 | C30: =$B$16 -> 6300000 | D30: =B30/C30 -> 0.0031746032 | E30: $20k committed; $13k received and $7k expected soon. SAFE treatment remains hypothetical.
A31: Soft investor — if diligence and close succeed | B31: =$B$12 -> 50000 | C31: =$B$16 -> 6300000 | D31: =B31/C31 -> 0.0079365079 | E31: Conditional $50k; no allocation guaranteed
A32: Other early investors / replacement allocation | B32: =$B$7-SUM(B30:B31) -> 230000 | C32: =$B$16 -> 6300000 | D32: =B32/C32 -> 0.036507937 | E32: Unidentified balance of early allocation
A33: Standard investors / unallocated balance | B33: =$B$17 -> 650000 | C33: =$B$15 -> 7000000 | D33: =B33/C33 -> 0.092857143 | E33: Unidentified balance; no committed capital implied
A34: Total | B34: =SUM(B28:B33) -> 950000 | D34: =SUM(D28:D33) -> 1 | E34: Single $950k full-raise illustration
A35: All investor ownership | B35: =SUM(B30:B33) -> 950000 | D35: =SUM(D30:D33) -> 0.14047619 | E35: Compare with 20% ceiling; contingent on conversion assumptions
A37: Funding reality — separate from full-raise illustration | B37: USD / value | C37: Interpretation
A38: Commitments plus conditional indications | B38: ='Investor Register'!B16 -> 70000 | C38: $20k relative commitment + $50k conditional verbal interest; not closed equity
A39: Cash actually received | B39: ='Investor Register'!C16 -> 13000 | C39: $13k relative funding; instrument unresolved
A40: Indicated balance not received | B40: =B38-B39 -> 57000 | C40: $7k committed balance expected soon + $50k conditional verbal interest
A41: Signed SAFE principal reported | B41: ='Investor Register'!D16 -> 0 | C41: No finalized SAFE reported; document evidence required
A42: Documented and funded SAFE principal | B42: ='Investor Register'!K16 -> 0 | C42: No completed SAFE funding documented in this working model
A43: Cash to reach gross $950k, if all receipts count | B43: =B6-B39 -> 937000 | C43: Conditional $937k; do not subtract unreceived indications
A44: Modeled equity capital still unclosed | B44: =B6-B42 -> 950000 | C44: $950k until unresolved first investor cash is formally treated as equity
A46: Pool sizing and checks | B46: Result | C46: Interpretation
...

Sheet Investor Register
A1: Jalla — investor commitments and funding register
A2: Founder-reported as of 22 October 2026. Indications, cash received and signed securities are separate. Blank evidence fields mean supporting records have not yet been attached.
A3: Blue values are editable. Enter signed SAFE principal/cap and a document link only after execution; funded SAFE principal is limited to cash received.
A4: Investor / reference | B4: Commitment / indication USD | C4: Cash received USD | D4: Signed SAFE principal USD | E4: Proposed allocation | F4: Signed post-money cap USD | G4: Current status | H4: Supporting document / source URL | I4: Next action | J4: Last reviewed | K4: Documented funded SAFE USD | L4: Cap-based ownership
A5: Wuba Ofe | B5: 20000 | C5: 13000 | D5: 0 | E5: Early | G5: $20k committed; $13k received; $7k expected soon; instrument unresolved | I5: Receive remaining $7k; document loan-versus-equity terms | J5: 2026-10-22 | K5: =IF(AND(D5>0,ISNUMBER(F5),F5>0,H5<>""),MIN(C5,D5),0) -> 0 | L5: =IF(K5>0,K5/F5,0) -> 0
A6: Joe Campanella | B6: 50000 | C6: 0 | D6: 0 | E6: Early | G6: Verbal; due diligence pending | I6: Complete independent due diligence; no signed or funded investment | J6: 2026-10-22 | K6: =IF(AND(D6>0,ISNUMBER(F6),F6>0,H6<>""),MIN(C6,D6),0) -> 0 | L6: =IF(K6>0,K6/F6,0) -> 0
K7: =IF(AND(D7>0,ISNUMBER(F7),F7>0,H7<>""),MIN(C7,D7),0) -> 0 | L7: =IF(K7>0,K7/F7,0) -> 0
K8: =IF(AND(D8>0,ISNUMBER(F8),F8>0,H8<>""),MIN(C8,D8),0) -> 0 | L8: =IF(K8>0,K8/F8,0) -> 0
K9: =IF(AND(D9>0,ISNUMBER(F9),F9>0,H9<>""),MIN(C9,D9),0) -> 0 | L9: =IF(K9>0,K9/F9,0) -> 0
K10: =IF(AND(D10>0,ISNUMBER(F10),F10>0,H10<>""),MIN(C10,D10),0) -> 0 | L10: =IF(K10>0,K10/F10,0) -> 0
K11: =IF(AND(D11>0,ISNUMBER(F11),F11>0,H11<>""),MIN(C11,D11),0) -> 0 | L11: =IF(K11>0,K11/F11,0) -> 0
K12: =IF(AND(D12>0,ISNUMBER(F12),F12>0,H12<>""),MIN(C12,D12),0) -> 0 | L12: =IF(K12>0,K12/F12,0) -> 0
K13: =IF(AND(D13>0,ISNUMBER(F13),F13>0,H13<>""),MIN(C13,D13),0) -> 0 | L13: =IF(K13>0,K13/F13,0) -> 0
K14: =IF(AND(D14>0,ISNUMBER(F14),F14>0,H14<>""),MIN(C14,D14),0) -> 0 | L14: =IF(K14>0,K14/F14,0) -> 0
A16: Register totals | B16: =SUM(B5:B14) -> 70000 | C16: =SUM(C5:C14) -> 13000 | D16: =SUM(D5:D14) -> 0 | K16: =SUM(K5:K14) -> 0 | L16: =SUM(L5:L14) -> 0
A17: Committed / indicated balance not received | B17: =B16-C16 -> 57000 | C17: $7k committed by first investor, expected soon; $50k investor interest is conditional on due diligence.
A18: Cash versus security | B18: The $13k is received funding with unresolved terms, not documented SAFE equity. Do not treat it as a completed equity close.
A19: Update rule | B19: Indicated total includes amounts received. Never add B and C together. Unknown investor names stay unresolved until identified.
A20: Signed terms control | B20: Proposed Early/Standard band does not establish a cap. Enter the actual signed cap in F; the ownership calculation uses F, not the scenario cap.
A21: Relative funding assumption | B21: The full-raise illustration assumes the entire $20k becomes an early SAFE within the $950k. This is not agreed. If it becomes a loan, replace this equity allocation and review repayment cash needs.
A22: Soft commitment assumption | B22: The $50k is shown as a possible early allocation in the full-raise illustration only. No early allocation is reserved and no terms or equity are granted.
A23: Scope | B23: Cap-based SAFE ownership is before priced-round new money/pool changes and assumes cap conversion. It is not current issued stock ownership.
A24: Source | B24: Founder statements in this discussion; supporting subscription, share issuance and bank records not inspected.
A25: Wuba Ofe — total committed | B25: =B5 -> 20000
A26: Wuba Ofe— received | B26: =C5 -> 13000
A27: Wuba Ofe — committed balance expected soon | B27: =B5-C5 -> 7000
