Workbook

Sheet Sheet2
A1: CONSTRUCTION ESTIMATE OF G+1 SCHOOL BUILDING BELONGING TO Mr BABILA Pascal GWANVOMA (NAKA-BALI NYONGA)
A2: Art. N0 | B2: DESIGNATION | C2: UNITS | D2: QUANTITY | E2: UNIT PRICE | F2: TOTAL
A3: 100 | B3: PRILIMINARY WORKS
A4: 101 | B4: Site Installation | C4: FF | D4: 1 | E4: 200000 | F4: =D4*E4 -> 200000
A5: 102 | B5: Land escavation and levels creation | C5: FF | D5: 1 | E5: 500000 | F5: =D5*E5 -> 500000
A6: 103 | B6: water evaquation and canalysation of flood water | C6: ff | D6: 1 | E6: 130000 | F6: =D6*E6 -> 130000
B7: TOTAL PREPARATORY WORKS | F7: =SUM(F4:F6) -> 830000
A8: 200 | B8: FOUNDATION
A9: 201 | B9: Excavation of foundation pits and trenches | C9: m3 | D9: =6*4*6*1.3*0.6 -> 112.32 | E9: 1000 | F9: =D9*E9 -> 112320
A10: 202 | B10: Backfill of foundation | C10: m3 | D10: =D9-D11-D12-D13-D16 -> 59.346 | E10: 500 | F10: =D10*E10 -> 29673
A11: 203 | B11: Lean concrete of thickness 5cm dosed at 150kg/m3 | C11: m3 | D11: =6*6*4*0.6*0.05 -> 4.32 | E11: ='unit cost calculation'!F24 -> 38800 | F11: =D11*E11 -> 167616
A12: 204 | B12: Reinforced concrete for footings 350kg/m3 | C12: m3 | D12: =1.2*1.2*0.3*27 -> 11.664 | E12: ='unit cost calculation'!F22 -> 190000 | F12: =D12*E12 -> 2216160
A13: 205 | B13: Reinforced concrete for foundation pillers 350kg/m3 | C13: m3 | D13: =0.3*0.25*1.2*27 -> 2.43 | E13: ='unit cost calculation'!F22 -> 190000 | F13: =D13*E13 -> 461700
A14: 206 | B14: Reinforced concrete for foundation beams 350kg/m3 | C14: m3 | D14: =(6*6*4)*0.15*0.3 -> 6.48 | E14: 180000 | F14: =D14*E14 -> 1166400
A15: 207 | B15: Lightly Concreted flooring (7cm) dosed at 250kg/m3 | C15: m3 | D15: =72*2*0.12 -> 17.28 | E15: ='unit cost calculation'!F29 -> 71000 | F15: =D15*E15 -> 1226880
A16: 208 | B16: 20cm filled foundation blocks | C16: m2 | D16: =(6*6*4)*0.2*1.2 -> 34.56 | E16: 1750 | F16: =D16*E16 -> 60480
A17: 209 | B17: poltystrene film | C17: m2 | D17: =D15 -> 17.28 | E17: 1000 | F17: =D17*E17 -> 17280
A18: 210 | B18: 5cm layer of sand | C18: m2 | D18: =D17 -> 17.28 | E18: 1000 | F18: =D18*E18 -> 17280
B19: TOTAL FOUNDATION | F19: =SUM(F9:F18) -> 5475789
A20: 300 | B20: GROUND FLOOR ELEVATION
A21: 301 | B21: Reinforced concrete for pillers 350kg/m3 | C21: m3 | D21: =0.3*0.25*2.7 -> 0.2025 | E21: ='unit cost calculation'!F22 -> 190000 | F21: =D21*E21 -> 38475
A22: 302 | B22: Reinforced concrete for beams and lintel 350kg/m3 | C22: m3 | D22: =D14 -> 6.48 | E22: ='unit cost calculation'!F22 -> 190000 | F22: =D22*E22 -> 1231200
A23: 303 | B23: Reinforced concrete for Staircase 350kg/m3 | C23: m3 | D23: 5 | E23: ='unit cost calculation'!F22 -> 190000 | F23: =D23*E23 -> 950000
A24: 304 | B24: Reinforced concrete Slab 350kg/m3 | C24: m3 | D24: =D15 -> 17.28 | E24: ='unit cost calculation'!F22 -> 190000 | F24: =D24*E24 -> 3283200
A25: 305 | B25: 15cm sandcrete blocks | C25: m2 | D25: =(72*2/0.4)*0.2*13 -> 936 | E25: 1750 | F25: =D25*E25 -> 1638000
A26: 306 | B26: Internal and external pastering (ep =2cm) dosed at 400kg/m3 | C26: m2 | D26: =72*2.7*4 -> 777.6 | E26: 7200 | F26: =D26*E26 -> 5598720
A27: 307 | B27: Plastering for slab dosed at 400kg/m3 | C27: m2 | D27: =72*2 -> 144 | E27: 7200 | F27: =D27*E27 -> 1036800
A28: 308 | B28: Mortar flooring | C28: m2 | D28: =D27*0.02 -> 2.88 | E28: 7200 | F28: =D28*E28 -> 20736
A29: 309 | B29: Floor tiles | C29: m2 | D29: 36 | E29: 10900 | F29: =D29*E29 -> 392400
A30: 310 | B30: Wall tiles | C30: m2 | D30: 25 | E30: 9000 | F30: =D30*E30 -> 225000
A31: 311 | B31: Staffing | C31: m2 | D31: 0 | E31: 14000 | F31: =D31*E31 -> 0
B32: TOTAL GROUND FLOOR ELEVATION | F32: =SUM(F21:F31) -> 14414531
A33: 400 | B33: FIRST FLOOR ELEVATION
A34: 401 | B34: Reinforced concrete for pillers 350kg/m3 | C34: m3 | D34: =D21 -> 0.2025 | E34: ='unit cost calculation'!F22 -> 190000 | F34: =D34*E34 -> 38475
A35: 402 | B35: Reinforced concrete for beams and lintel 350kg/m3 | C35: m3 | D35: =D22 -> 6.48 | E35: ='unit cost calculation'!F22 -> 190000 | F35: =D35*E35 -> 1231200
A36: 403 | B36: 15cm sandcrete blocks | C36: m2 | D36: =D25 -> 936 | E36: =E25 -> 1750 | F36: =D36*E36 -> 1638000
A37: 404 | B37: Internal and external pastering (ep =2cm) dosed at 400kg/m3 | C37: m2 | D37: =D26 -> 777.6 | E37: =E26 -> 7200 | F37: =D37*E37 -> 5598720
A38: 405 | B38: Mortar flooring | C38: m2 | D38: =D28 -> 2.88 | E38: 10900 | F38: =D38*E38 -> 31392
A39: 406 | B39: Floor tiles | C39: m2 | D39: 0 | E39: 10900 | F39: =D39*E39 -> 0
A40: 407 | B40: Wall tiles | C40: m2 | D40: 0 | E40: 16000 | F40: =D40*E40 -> 0
...

Sheet unit cost calculation
A1: CALCULATION OF UNIT COST BASED ON MATERIAL PRICE VARIATION PER REGION.
A3: COST COMPONENT | B3: FORMULATION/INPUT | C3: COST IN DOUALA | D3: COST IN BUEA | E3: COST IN LIMBE | F3: COST IN BALI | G3: COST IN ADAMAWA | H3: COST IN YAOUNDE | I3: COST IN KRIBI | J3: COST IN ABUJA
A4: cement 350kg/m3=7bags | B4: base rate + transport | C4: =7*5000 -> 35000 | D4: =7*5500 -> 38500 | E4: =7*5400 -> 37800 | F4: =7*6000 -> 42000 | G4: =7*6500 -> 45500 | H4: =7*5000 -> 35000 | I4: =7*4900 -> 34300 | J4: =7*11000 -> 77000
A5: cement 250kg/m3=5 bags | B5: base rate + transport | C5: =5*5000 -> 25000 | D5: =5*5500 -> 27500 | E5: =5*5400 -> 27000 | F5: =5*6000 -> 30000 | G5: =5*6500 -> 32500 | H5: =5*5000 -> 25000 | I5: =5*4900 -> 24500 | J5: =5*11000 -> 55000
A6: cement 150kg/m3=2 bags | B6: base rate + transport | C6: =2*5000 -> 10000 | D6: =2*5500 -> 11000 | E6: =2*5400 -> 10800 | F6: =2*6000 -> 12000 | G6: =2*6500 -> 13000 | H6: =2*5000 -> 10000 | I6: =2*4900 -> 9800 | J6: =2*11000 -> 22000
A8: sand (0.4m3) | B8: river/quary + transport | C8: =0.4*12000 -> 4800 | D8: =0.4*14000 -> 5600 | E8: =0.4*12000 -> 4800 | F8: =0.4*12000 -> 4800 | G8: =0.4*18000 -> 7200 | H8: =0.4*17000 -> 6800 | I8: =0.4*13000 -> 5200 | J8: =0.4*14000 -> 5600
A9: gravel (0,8m3) | B9: crushed rock + transport | C9: =0.8*16000 -> 12800 | D9: =0.8*14000 -> 11200 | E9: =0.8*14000 -> 11200 | F9: =0.8*13000 -> 10400 | G9: =0.8*14000 -> 11200 | H9: =0.8*10000 -> 8000 | I9: =0.8*18000 -> 14400 | J9: =0.8*9000 -> 7200
A10: steel(HY400) | B10: 85kg | C10: =650*85 -> 55250 | D10: =750*85 -> 63750 | E10: =750*85 -> 63750 | F10: =800*85 -> 68000 | G10: ` | H10: =650*85 -> 55250 | I10: =700*85 -> 59500 | J10: =2000*85 -> 170000
A11: binding wire | B11: 1.5kg | C11: =1000*1.5 -> 1500 | D11: =1100*1.5 -> 1650 | E11: =1100*1.5 -> 1650 | F11: =1000*1.5 -> 1500 | G11: =1500*1.5 -> 2250 | H11: =1000*1.5 -> 1500 | I11: =1000*1.5 -> 1500 | J11: =2500*1.5 -> 3750
A12: formwork | B12: 2.5m2 timber | C12: =3500*2.5 -> 8750 | D12: =3500*2.5 -> 8750 | E12: =3500*2.5 -> 8750 | F12: =3500*2.5 -> 8750 | G12: =5500*2.5 -> 13750 | H12: =4500*2.5 -> 11250 | I12: =3000*2.5 -> 7500 | J12: =14000*2.5 -> 35000
A13: poles/ surport/chevron | B13: ls | C13: 3000 | D13: 3200 | E13: 3000 | F13: 3500 | G13: 4000 | H13: 3200 | I13: 2800 | J13: 7000
A14: labor (bar bending) | B14: iron work | C14: 3000 | D14: 3000 | E14: 3000 | F14: 1500 | G14: 3000 | H14: 3000 | I14: 3000 | J14: 3000
A15: labor (formwork) | B15: formwork | C15: 1000 | D15: 1000 | E15: 1000 | F15: 500 | G15: 1000 | H15: 1000 | I15: 1000 | J15: 1000
A16: water(180L) | B16: tanker/local suply | C16: =5000/5 -> 1000 | D16: =5000/5 -> 1000 | E16: =5000/5 -> 1000 | F16: =3000/5 -> 600 | G16: =5000/5 -> 1000 | H16: =5000/5 -> 1000 | I16: =5000/5 -> 1000 | J16: =12000/5 -> 2400
A17: labor(mixing and pouring) | B17: ( 1 macon + 3 laborers) | C17: 12000 | D17: 12000 | E17: 12000 | F17: 10000 | G17: 16000 | H17: 12000 | I17: 12000 | J17: 24000
A18: inspection | B18: through 10 stages | C18: 1000 | D18: 1000 | E18: 1000 | F18: 1000 | G18: 1000 | H18: 1000 | I18: 1000 | J18: 1000
A19: equipment | B19: daily allocation | C19: 2000 | D19: 2500 | E19: 2000 | F19: 3500 | G19: 5000 | H19: 2000 | I19: 3000 | J19: 7000
A20: direct cost (DC) | B20: sum of the above | C20: =SUM(C4,C8:C18) -> 139100 | D20: =SUM(D4,D8:D18) -> 150650 | E20: =SUM(E4,E8:E18) -> 148950 | F20: =SUM(F4,F8:F18) -> 152550 | G20: =SUM(G4,G8:G18) -> 105900 | H20: =SUM(H4,H8:H18) -> 139000 | I20: =SUM(I4,I8:I18) -> 143200 | J20: =SUM(J4,J8:J18) -> 336950
A21: overheads +profits(25%) | B21: DC*1.25 | C21: =C20*1.25 -> 173875 | D21: =D20*1.25 -> 188312.5 | E21: =E20*1.25 -> 186187.5 | F21: =F20*1.25 -> 190687.5 | G21: =G20*1.25 -> 132375 | H21: =H20*1.25 -> 173750 | I21: =I20*1.25 -> 179000 | J21: =J20*1.25 -> 421187.5
A22: TOTAL COST PUA. | B22: XAF/NGN | C22: 180000 | D22: 190000 | E22: 190000 | F22: 190000 | G22: 260000 | H22: 180000 | I22: =I21 -> 179000 | J22: 450000
A24: LEAN CONCRETE | C24: =C6+C8+C9+C16+C17+C18 -> 41600 | D24: =D6+D8+D9+D16+D17+D18 -> 41800 | E24: =E6+E8+E9+E16+E17+E18 -> 40800 | F24: =F6+F8+F9+F16+F17+F18 -> 38800 | G24: =G6+G8+G9+G16+G17+G18 -> 49400 | H24: =H6+H8+H9+H16+H17+H18 -> 38800 | I24: =I6+I8+I9+I16+I17+I18 -> 43400 | J24: =J6+J8+J9+J16+J17+J18 -> 62200
A25: overheads +profits(25%) | B25: DC*1.25 | C25: =C24*1.25 -> 52000 | D25: =D24*1.25 -> 52250 | E25: =E24*1.25 -> 51000 | F25: =F24*1.25 -> 48500 | G25: =G24*1.25 -> 61750 | H25: =H24*1.25 -> 48500 | I25: =I24*1.25 -> 54250 | J25: =J24*1.25 -> 77750
A28: CONCRETE 250KG | C28: =C5+C8+C9+C16+C17+C18 -> 56600 | D28: =D5+D8+D9+D16+D17+D18 -> 58300 | E28: =E5+E8+E9+E16+E17+E18 -> 57000 | F28: =F5+F8+F9+F16+F17+F18 -> 56800 | G28: =G5+G8+G9+G16+G17+G18 -> 68900 | H28: =H5+H8+H9+H16+H17+H18 -> 53800 | I28: =I5+I8+I9+I16+I17+I18 -> 58100 | J28: =J5+J8+J9+J16+J17+J18 -> 95200
A29: overheads +profits(25%) | B29: DC*1.25 | C29: =C28*1.25 -> 70750 | D29: =D28*1.25 -> 72875 | E29: =E28*1.25 -> 71250 | F29: =F28*1.25 -> 71000 | G29: =G28*1.25 -> 86125 | H29: =H28*1.25 -> 67250 | I29: =I28*1.25 -> 72625 | J29: =J28*1.25 -> 119000
A32: MORTAR | C32: =C4+C8+C15+C17+C18 -> 53800 | D32: =D4+D8+D15+D17+D18 -> 58100 | E32: =E4+E8+E15+E17+E18 -> 56600 | F32: =F4+F8+F15+F17+F18 -> 58300 | G32: =G4+G8+G15+G17+G18 -> 70700 | H32: =H4+H8+H15+H17+H18 -> 55800 | I32: =I4+I8+I15+I17+I18 -> 53500 | J32: =J4+J8+J15+J17+J18 -> 108600
A33: overheads +profits(25%) | B33: DC*1.25 | C33: =C32*1.25 -> 67250 | D33: =D32*1.25 -> 72625 | E33: =E32*1.25 -> 70750 | F33: =F32*1.25 -> 72875 | G33: =G32*1.25 -> 88375 | H33: =H32*1.25 -> 69750 | I33: =I32*1.25 -> 66875 | J33: =J32*1.25 -> 135750
